<mujoco model="ant">
  <size njmax="2000" nconmax="1000"/>
  <compiler angle="degree" coordinate="local" inertiafromgeom="true"/>
  <option integrator="RK4" timestep="0.005"/>
  <custom>
    <numeric data="0.0 0.0 0.55 1.0 0.0 0.0 0.0 0.0 1.0 0.0 -1.0 0.0 -1.0 0.0 1.0" name="init_qpos"/>
  </custom>
  <default>
    <joint armature="1" damping="1" limited="true"/>
    <geom conaffinity="0" condim="3" density="5.0" friction="1 0.5 0.5" margin="0.01" rgba="0.8 0.6 0.4 1"/>
  </default>
  <asset>
    <texture builtin="gradient" height="100" rgb1="1 1 1" rgb2="0 0 0" type="skybox" width="100"/>
    <texture builtin="flat" height="1278" mark="cross" markrgb="1 1 1" name="texgeom" random="0.01" rgb1="0.8 0.6 0.4" rgb2="0.8 0.6 0.4" type="cube" width="127"/>
    <texture builtin="checker" height="100" name="texplane" rgb1="0 0 0" rgb2="0.8 0.8 0.8" type="2d" width="100"/>
    <material name="MatPlane" reflectance="0.5" shininess="1" specular="1" texrepeat="60 60" texture="texplane"/>
    <material name="geom" texture="texgeom" texuniform="true"/>
  </asset>
  <worldbody>
    <light cutoff="100" diffuse="1 1 1" dir="-0 0 -1.3" directional="true" exponent="1" pos="0 0 1.3" specular=".1 .1 .1"/>
    <geom conaffinity="1" condim="3" material="MatPlane" name="floor" pos="0 0 0" rgba="0.8 0.9 0.8 1" size="40 40 40" type="plane"/>
    <body name="torso_0" pos="0 0 0.75">
      <camera name="track" mode="trackcom" pos="0 -3 0.3" xyaxes="1 0 0 0 0 1"/>
      <!--<geom density="1000" fromto="0 0 0 -1 0 0" size="0.1" type="capsule"/>-->
      <joint armature="0" damping="0" limited="false" margin="0.01" name="root" pos="0 0 0" type="free"/>
      <body name="front_left_leg_0" pos="0 0 0">
        <geom fromto="0.0 0.0 0.0 0.2 0.2 0.0" name="aux1_geom_0" size="0.08" type="capsule"/>
        <body name="aux1_0" pos="0.2 0.2 0">
          <joint axis="0 0 1" name="hip1_0" pos="0.0 0.0 0.0" range="-30 30" type="hinge"/>
          <geom fromto="0.0 0.0 0.0 0.2 0.2 0.0" name="left_leg_geom_0" size="0.08" type="capsule"/>
          <body pos="0.2 0.2 0">
            <joint axis="-1 1 0" name="ankle1_0" pos="0.0 0.0 0.0" range="30 70" type="hinge"/>
            <geom fromto="0.0 0.0 0.0 0.4 0.4 0.0" name="left_ankle_geom_0" size="0.08" type="capsule"/>
          </body>
        </body>
      </body>
      <body name="right_back_leg_0" pos="0 0 0">
        <geom fromto="0.0 0.0 0.0 0.2 -0.2 0.0" name="aux2_geom_0" size="0.08" type="capsule"/>
        <body name="aux2_0" pos="0.2 -0.2 0">
          <joint axis="0 0 1" name="hip2_0" pos="0.0 0.0 0.0" range="-30 30" type="hinge"/>
          <geom fromto="0.0 0.0 0.0 0.2 -0.2 0.0" name="rightback_leg_geom_0" size="0.08" type="capsule"/>
          <body pos="0.2 -0.2 0">
            <joint axis="1 1 0" name="ankle2_0" pos="0.0 0.0 0.0" range="30 70" type="hinge"/>
            <geom fromto="0.0 0.0 0.0 0.4 -0.4 0.0" name="second_ankle_geom_0" size="0.08" type="capsule"/>
          </body>
        </body>
      </body>
      
        <body name="torso_1" pos="-1 0 0">
           <!--<joint axis="0 1 0" name="nnn_1" pos="0.0 0.0 0.0" range="-1 1" type="hinge"/>-->
            <geom density="100" fromto="1 0 0 0 0 0" size="0.1" type="capsule"/>
            <body name="front_right_leg_1" pos="0 0 0">
              <geom fromto="0.0 0.0 0.0 0.0 0.2 0.0" name="aux1_geom_1" size="0.08" type="capsule"/>
              <body name="aux_2_1" pos="0.0 0.2 0">
                <joint axis="0 0 1" name="hip1_1" pos="0.0 0.0 0.0" range="-30 30" type="hinge"/>
                <geom fromto="0.0 0.0 0.0 -0.2 0.2 0.0" name="right_leg_geom_1" size="0.08" type="capsule"/>
                <body pos="-0.2 0.2 0">
                  <joint axis="1 1 0" name="ankle1_1" pos="0.0 0.0 0.0" range="-70 -30" type="hinge"/>
                  <geom fromto="0.0 0.0 0.0 -0.4 0.4 0.0" name="right_ankle_geom_1" size="0.08" type="capsule"/>
                </body>
              </body>
            </body>
            <body name="back_leg_1" pos="0 0 0">
              <geom fromto="0.0 0.0 0.0 0.0 -0.2 0.0" name="aux2_geom_1" size="0.08" type="capsule"/>
              <body name="aux2_1" pos="0.0 -0.2 0">
                <joint axis="0 0 1" name="hip2_1" pos="0.0 0.0 0.0" range="-30 30" type="hinge"/>
                <geom fromto="0.0 0.0 0.0 -0.2 -0.2 0.0" name="back_leg_geom_1" size="0.08" type="capsule"/>
                <body pos="-0.2 -0.2 0">
                  <joint axis="-1 1 0" name="ankle2_1" pos="0.0 0.0 0.0" range="-70 -30" type="hinge"/>
                  <geom fromto="0.0 0.0 0.0 -0.4 -0.4 0.0" name="third_ankle_geom_1" size="0.08" type="capsule"/>
                </body>
              </body>
            </body>
        
        <body name="torso_2" pos="-1 0 0">
           <!--<joint axis="0 1 0" name="nnn_2" pos="0.0 0.0 0.0" range="-1 1" type="hinge"/>-->
            <geom density="100" fromto="1 0 0 0 0 0" size="0.1" type="capsule"/>
            <body name="front_right_leg_2" pos="0 0 0">
              <geom fromto="0.0 0.0 0.0 0.0 0.2 0.0" name="aux1_geom_2" size="0.08" type="capsule"/>
              <body name="aux_2_2" pos="0.0 0.2 0">
                <joint axis="0 0 1" name="hip1_2" pos="0.0 0.0 0.0" range="-30 30" type="hinge"/>
                <geom fromto="0.0 0.0 0.0 -0.2 0.2 0.0" name="right_leg_geom_2" size="0.08" type="capsule"/>
                <body pos="-0.2 0.2 0">
                  <joint axis="1 1 0" name="ankle1_2" pos="0.0 0.0 0.0" range="-70 -30" type="hinge"/>
                  <geom fromto="0.0 0.0 0.0 -0.4 0.4 0.0" name="right_ankle_geom_2" size="0.08" type="capsule"/>
                </body>
              </body>
            </body>
            <body name="back_leg_2" pos="0 0 0">
              <geom fromto="0.0 0.0 0.0 0.0 -0.2 0.0" name="aux2_geom_2" size="0.08" type="capsule"/>
              <body name="aux2_2" pos="0.0 -0.2 0">
                <joint axis="0 0 1" name="hip2_2" pos="0.0 0.0 0.0" range="-30 30" type="hinge"/>
                <geom fromto="0.0 0.0 0.0 -0.2 -0.2 0.0" name="back_leg_geom_2" size="0.08" type="capsule"/>
                <body pos="-0.2 -0.2 0">
                  <joint axis="-1 1 0" name="ankle2_2" pos="0.0 0.0 0.0" range="-70 -30" type="hinge"/>
                  <geom fromto="0.0 0.0 0.0 -0.4 -0.4 0.0" name="third_ankle_geom_2" size="0.08" type="capsule"/>
                </body>
              </body>
            </body>
        
        <body name="torso_3" pos="-1 0 0">
           <!--<joint axis="0 1 0" name="nnn_3" pos="0.0 0.0 0.0" range="-1 1" type="hinge"/>-->
            <geom density="100" fromto="1 0 0 0 0 0" size="0.1" type="capsule"/>
            <body name="front_right_leg_3" pos="0 0 0">
              <geom fromto="0.0 0.0 0.0 0.0 0.2 0.0" name="aux1_geom_3" size="0.08" type="capsule"/>
              <body name="aux_2_3" pos="0.0 0.2 0">
                <joint axis="0 0 1" name="hip1_3" pos="0.0 0.0 0.0" range="-30 30" type="hinge"/>
                <geom fromto="0.0 0.0 0.0 -0.2 0.2 0.0" name="right_leg_geom_3" size="0.08" type="capsule"/>
                <body pos="-0.2 0.2 0">
                  <joint axis="1 1 0" name="ankle1_3" pos="0.0 0.0 0.0" range="-70 -30" type="hinge"/>
                  <geom fromto="0.0 0.0 0.0 -0.4 0.4 0.0" name="right_ankle_geom_3" size="0.08" type="capsule"/>
                </body>
              </body>
            </body>
            <body name="back_leg_3" pos="0 0 0">
              <geom fromto="0.0 0.0 0.0 0.0 -0.2 0.0" name="aux2_geom_3" size="0.08" type="capsule"/>
              <body name="aux2_3" pos="0.0 -0.2 0">
                <joint axis="0 0 1" name="hip2_3" pos="0.0 0.0 0.0" range="-30 30" type="hinge"/>
                <geom fromto="0.0 0.0 0.0 -0.2 -0.2 0.0" name="back_leg_geom_3" size="0.08" type="capsule"/>
                <body pos="-0.2 -0.2 0">
                  <joint axis="-1 1 0" name="ankle2_3" pos="0.0 0.0 0.0" range="-70 -30" type="hinge"/>
                  <geom fromto="0.0 0.0 0.0 -0.4 -0.4 0.0" name="third_ankle_geom_3" size="0.08" type="capsule"/>
                </body>
              </body>
            </body>
        
        <body name="torso_4" pos="-1 0 0">
           <!--<joint axis="0 1 0" name="nnn_4" pos="0.0 0.0 0.0" range="-1 1" type="hinge"/>-->
            <geom density="100" fromto="1 0 0 0 0 0" size="0.1" type="capsule"/>
            <body name="front_right_leg_4" pos="0 0 0">
              <geom fromto="0.0 0.0 0.0 0.0 0.2 0.0" name="aux1_geom_4" size="0.08" type="capsule"/>
              <body name="aux_2_4" pos="0.0 0.2 0">
                <joint axis="0 0 1" name="hip1_4" pos="0.0 0.0 0.0" range="-30 30" type="hinge"/>
                <geom fromto="0.0 0.0 0.0 -0.2 0.2 0.0" name="right_leg_geom_4" size="0.08" type="capsule"/>
                <body pos="-0.2 0.2 0">
                  <joint axis="1 1 0" name="ankle1_4" pos="0.0 0.0 0.0" range="-70 -30" type="hinge"/>
                  <geom fromto="0.0 0.0 0.0 -0.4 0.4 0.0" name="right_ankle_geom_4" size="0.08" type="capsule"/>
                </body>
              </body>
            </body>
            <body name="back_leg_4" pos="0 0 0">
              <geom fromto="0.0 0.0 0.0 0.0 -0.2 0.0" name="aux2_geom_4" size="0.08" type="capsule"/>
              <body name="aux2_4" pos="0.0 -0.2 0">
                <joint axis="0 0 1" name="hip2_4" pos="0.0 0.0 0.0" range="-30 30" type="hinge"/>
                <geom fromto="0.0 0.0 0.0 -0.2 -0.2 0.0" name="back_leg_geom_4" size="0.08" type="capsule"/>
                <body pos="-0.2 -0.2 0">
                  <joint axis="-1 1 0" name="ankle2_4" pos="0.0 0.0 0.0" range="-70 -30" type="hinge"/>
                  <geom fromto="0.0 0.0 0.0 -0.4 -0.4 0.0" name="third_ankle_geom_4" size="0.08" type="capsule"/>
                </body>
              </body>
            </body>
        
        <body name="torso_5" pos="-1 0 0">
           <!--<joint axis="0 1 0" name="nnn_5" pos="0.0 0.0 0.0" range="-1 1" type="hinge"/>-->
            <geom density="100" fromto="1 0 0 0 0 0" size="0.1" type="capsule"/>
            <body name="front_right_leg_5" pos="0 0 0">
              <geom fromto="0.0 0.0 0.0 0.0 0.2 0.0" name="aux1_geom_5" size="0.08" type="capsule"/>
              <body name="aux_2_5" pos="0.0 0.2 0">
                <joint axis="0 0 1" name="hip1_5" pos="0.0 0.0 0.0" range="-30 30" type="hinge"/>
                <geom fromto="0.0 0.0 0.0 -0.2 0.2 0.0" name="right_leg_geom_5" size="0.08" type="capsule"/>
                <body pos="-0.2 0.2 0">
                  <joint axis="1 1 0" name="ankle1_5" pos="0.0 0.0 0.0" range="-70 -30" type="hinge"/>
                  <geom fromto="0.0 0.0 0.0 -0.4 0.4 0.0" name="right_ankle_geom_5" size="0.08" type="capsule"/>
                </body>
              </body>
            </body>
            <body name="back_leg_5" pos="0 0 0">
              <geom fromto="0.0 0.0 0.0 0.0 -0.2 0.0" name="aux2_geom_5" size="0.08" type="capsule"/>
              <body name="aux2_5" pos="0.0 -0.2 0">
                <joint axis="0 0 1" name="hip2_5" pos="0.0 0.0 0.0" range="-30 30" type="hinge"/>
                <geom fromto="0.0 0.0 0.0 -0.2 -0.2 0.0" name="back_leg_geom_5" size="0.08" type="capsule"/>
                <body pos="-0.2 -0.2 0">
                  <joint axis="-1 1 0" name="ankle2_5" pos="0.0 0.0 0.0" range="-70 -30" type="hinge"/>
                  <geom fromto="0.0 0.0 0.0 -0.4 -0.4 0.0" name="third_ankle_geom_5" size="0.08" type="capsule"/>
                </body>
              </body>
            </body>
        </body>
</body>
</body>
</body>
</body>

    </body>
  </worldbody>
  <actuator>
    	     <motor ctrllimited="true" ctrlrange="-1.0 1.0" joint="hip1_0" gear="150"/>
                                          <motor ctrllimited="true" ctrlrange="-1.0 1.0" joint="ankle1_0" gear="150"/>
                                          <motor ctrllimited="true" ctrlrange="-1.0 1.0" joint="hip2_0" gear="150"/>
                                          <motor ctrllimited="true" ctrlrange="-1.0 1.0" joint="ankle2_0" gear="150"/>
	     <motor ctrllimited="true" ctrlrange="-1.0 1.0" joint="hip1_1" gear="150"/>
                                          <motor ctrllimited="true" ctrlrange="-1.0 1.0" joint="ankle1_1" gear="150"/>
                                          <motor ctrllimited="true" ctrlrange="-1.0 1.0" joint="hip2_1" gear="150"/>
                                          <motor ctrllimited="true" ctrlrange="-1.0 1.0" joint="ankle2_1" gear="150"/>
	     <motor ctrllimited="true" ctrlrange="-1.0 1.0" joint="hip1_2" gear="150"/>
                                          <motor ctrllimited="true" ctrlrange="-1.0 1.0" joint="ankle1_2" gear="150"/>
                                          <motor ctrllimited="true" ctrlrange="-1.0 1.0" joint="hip2_2" gear="150"/>
                                          <motor ctrllimited="true" ctrlrange="-1.0 1.0" joint="ankle2_2" gear="150"/>
	     <motor ctrllimited="true" ctrlrange="-1.0 1.0" joint="hip1_3" gear="150"/>
                                          <motor ctrllimited="true" ctrlrange="-1.0 1.0" joint="ankle1_3" gear="150"/>
                                          <motor ctrllimited="true" ctrlrange="-1.0 1.0" joint="hip2_3" gear="150"/>
                                          <motor ctrllimited="true" ctrlrange="-1.0 1.0" joint="ankle2_3" gear="150"/>
	     <motor ctrllimited="true" ctrlrange="-1.0 1.0" joint="hip1_4" gear="150"/>
                                          <motor ctrllimited="true" ctrlrange="-1.0 1.0" joint="ankle1_4" gear="150"/>
                                          <motor ctrllimited="true" ctrlrange="-1.0 1.0" joint="hip2_4" gear="150"/>
                                          <motor ctrllimited="true" ctrlrange="-1.0 1.0" joint="ankle2_4" gear="150"/>
	     <motor ctrllimited="true" ctrlrange="-1.0 1.0" joint="hip1_5" gear="150"/>
                                          <motor ctrllimited="true" ctrlrange="-1.0 1.0" joint="ankle1_5" gear="150"/>
                                          <motor ctrllimited="true" ctrlrange="-1.0 1.0" joint="hip2_5" gear="150"/>
                                          <motor ctrllimited="true" ctrlrange="-1.0 1.0" joint="ankle2_5" gear="150"/>

  </actuator>
</mujoco>